Workbook

Sheet Full dataset
A1: Sort ID | B1: Suburb | C1: Council Area 1 | D1: Council Area 2 | E1: Property Type | F1: Price | G1: Bedrooms | H1: Bathrooms | I1: Land Size (sqm) | J1: Year Built | K1: Sale Date | L1: Inspection Rating | M1: Agent Name | N1: Commission Rate (%) | O1: Council Rate ($/year) | P1: Distance to Nearest Station (km) | Q1: House Area (sqm) | R1: NAPLAN Score of Nearest School
A2: 5 | B2: Dee Why | E2: Apartment | F2: 1936967 | G2: 5 | H2: 1 | I2: 140 | J2: 1999 | K2: 45302 | L2: Good | M2: Ashley Brown | N2: 3.39 | O2: 1733 | P2: 3.32 | Q2: 302 | R2: 303
A3: 3 | B3: Berowra | E3: Villa | F3: 884945 | G3: 5 | H3: 2 | I3: 525 | J3: 2016 | K3: 45757 | L3: Poor | M3: Juan Martinez | N3: 2.47 | O3: 2294 | P3: 3.08 | Q3: 364 | R3: 520
A4: 4 | B4: Normanhurst | E4: House | F4: 526791 | G4: 2 | H4: 2 | I4: 691 | J4: 1951 | K4: 44957 | L4: Average | M4: Fernanda Lima | N4: 1.58 | O4: 2433 | P4: 2.54 | Q4: 146 | R4: 641
A5: 4 | B5: Granville | E5: Townhouse | F5: 962318 | G5: 6 | H5: 1 | I5: 491 | J5: 1990 | K5: 44415 | L5: Excellent | M5: Fatima Abiola | N5: 2.97 | O5: 1428 | P5: 3.04 | Q5: 392 | R5: 609
A6: 7 | B6: Dee Why | E6: House | F6: 2081519 | G6: 5 | H6: 2 | I6: 774 | J6: 1958 | K6: 45443 | L6: Average | M6: Carlos Silva | N6: 2.31 | O6: 1017 | P6: 1.43 | Q6: 309 | R6: 563
A7: 4 | B7: Earlwood | E7: House | F7: 2995613 | G7: 2 | H7: 2 | I7: 145 | J7: 1996 | K7: 45163 | L7: Good | M7: Mateusz Kowalski | N7: 2.68 | O7: 1568 | P7: 3.1 | Q7: 172 | R7: 512
A8: 7 | B8: Ultimo | E8: House | F8: 899433 | G8: 2 | H8: 1 | I8: 305 | J8: 1995 | K8: 44103 | L8: Good | M8: Jack Thompson | N8: 2.21 | O8: 2298 | P8: 4.07 | Q8: 122 | R8: 427
A9: 4 | B9: Hornsby | E9: House | F9: 1086020 | G9: 5 | H9: 3 | I9: 364 | J9: 2016 | K9: 44230 | L9: Average | M9: Mateusz Kowalski | N9: 2.47 | O9: 1250 | P9: 1.26 | Q9: 393 | R9: 431
A10: 3 | B10: Kensington | E10: Townhouse | F10: 1543087 | G10: 1 | H10: 1 | I10: 237 | J10: 1972 | K10: 44873 | L10: Excellent | M10: Sofia Rossi | N10: 2.15 | O10: 2068 | P10: 1.68 | Q10: 154 | R10: 569
A11: 1 | B11: Doonside | E11: Apartment | F11: 1866856 | G11: 3 | H11: 2 | I11: 832 | J11: 1990 | K11: 45550 | L11: Excellent | M11: Ashley Brown | N11: 1.72 | O11: 1843 | P11: 3.12 | Q11: 136 | R11: 410
A12: 0 | B12: Mount Druitt | E12: Apartment | F12: 2667413 | G12: 6 | H12: 2 | I12: 827 | J12: 2004 | K12: 45323 | L12: Excellent | M12: Chloe Wilson | N12: 3.3 | O12: 1568 | P12: 0.57 | Q12: 355 | R12: 426
A13: 5 | B13: Maroubra | E13: Villa | F13: 2373955 | G13: 2 | H13: 3 | I13: 885 | J13: 1965 | K13: 44448 | L13: Excellent | M13: Thabo Mokoena | N13: 2.38 | O13: 1779 | P13: 3.14 | Q13: 230 | R13: 426
... A3001: 0 | B3001: Northmead | E3001: House | F3001: 849482 | G3001: 1 | H3001: 1 | I3001: 651 | J3001: 2008 | K3001: 45793 | L3001: Poor | M3001: Minh Nguyen | N3001: 2.75 | O3001: 1035 | P3001: 2.81 | Q3001: 147 | R3001: 692

Sheet Q1
A1: Sort ID | B1: Suburb | C1: Council Area 1 | D1: Council Area 2 | E1: Property Type | F1: Price | G1: Bedrooms | H1: Bathrooms | I1: Land Size (sqm) | J1: Year Built | K1: Sale Date | L1: Inspection Rating | M1: Agent Name | N1: Commission Rate (%) | O1: Council Rate ($/year) | P1: Distance to Nearest Station (km) | Q1: House Area (sqm) | R1: NAPLAN Score of Nearest School
A2: 5 | B2: Dee Why | E2: Apartment | F2: 1936967 | G2: 5 | H2: 1 | I2: 140 | J2: 1999 | K2: 45302 | L2: Good | M2: Ashley Brown | N2: 3.39 | O2: 1733 | P2: 3.32 | Q2: 302 | R2: 303
A3: 3 | B3: Berowra | E3: Villa | F3: 884945 | G3: 5 | H3: 2 | I3: 525 | J3: 2016 | K3: 45757 | L3: Poor | M3: Juan Martinez | N3: 2.47 | O3: 2294 | P3: 3.08 | Q3: 364 | R3: 520
A4: 4 | B4: Normanhurst | E4: House | F4: 526791 | G4: 2 | H4: 2 | I4: 691 | J4: 1951 | K4: 44957 | L4: Average | M4: Fernanda Lima | N4: 1.58 | O4: 2433 | P4: 2.54 | Q4: 146 | R4: 641
A5: 4 | B5: Granville | E5: Townhouse | F5: 962318 | G5: 6 | H5: 1 | I5: 491 | J5: 1990 | K5: 44415 | L5: Excellent | M5: Fatima Abiola | N5: 2.97 | O5: 1428 | P5: 3.04 | Q5: 392 | R5: 609
A6: 7 | B6: Dee Why | E6: House | F6: 2081519 | G6: 5 | H6: 2 | I6: 774 | J6: 1958 | K6: 45443 | L6: Average | M6: Carlos Silva | N6: 2.31 | O6: 1017 | P6: 1.43 | Q6: 309 | R6: 563
A7: 4 | B7: Earlwood | E7: House | F7: 2995613 | G7: 2 | H7: 2 | I7: 145 | J7: 1996 | K7: 45163 | L7: Good | M7: Mateusz Kowalski | N7: 2.68 | O7: 1568 | P7: 3.1 | Q7: 172 | R7: 512
A8: 7 | B8: Ultimo | E8: House | F8: 899433 | G8: 2 | H8: 1 | I8: 305 | J8: 1995 | K8: 44103 | L8: Good | M8: Jack Thompson | N8: 2.21 | O8: 2298 | P8: 4.07 | Q8: 122 | R8: 427
A9: 4 | B9: Hornsby | E9: House | F9: 1086020 | G9: 5 | H9: 3 | I9: 364 | J9: 2016 | K9: 44230 | L9: Average | M9: Mateusz Kowalski | N9: 2.47 | O9: 1250 | P9: 1.26 | Q9: 393 | R9: 431
A10: 3 | B10: Kensington | E10: Townhouse | F10: 1543087 | G10: 1 | H10: 1 | I10: 237 | J10: 1972 | K10: 44873 | L10: Excellent | M10: Sofia Rossi | N10: 2.15 | O10: 2068 | P10: 1.68 | Q10: 154 | R10: 569
A11: 1 | B11: Doonside | E11: Apartment | F11: 1866856 | G11: 3 | H11: 2 | I11: 832 | J11: 1990 | K11: 45550 | L11: Excellent | M11: Ashley Brown | N11: 1.72 | O11: 1843 | P11: 3.12 | Q11: 136 | R11: 410
A12: 0 | B12: Mount Druitt | E12: Apartment | F12: 2667413 | G12: 6 | H12: 2 | I12: 827 | J12: 2004 | K12: 45323 | L12: Excellent | M12: Chloe Wilson | N12: 3.3 | O12: 1568 | P12: 0.57 | Q12: 355 | R12: 426
A13: 5 | B13: Maroubra | E13: Villa | F13: 2373955 | G13: 2 | H13: 3 | I13: 885 | J13: 1965 | K13: 44448 | L13: Excellent | M13: Thabo Mokoena | N13: 2.38 | O13: 1779 | P13: 3.14 | Q13: 230 | R13: 426
... A2996: 0 | B2996: Northmead | E2996: House | F2996: 849482 | G2996: 1 | H2996: 1 | I2996: 651 | J2996: 2008 | K2996: 45793 | L2996: Poor | M2996: Minh Nguyen | N2996: 2.75 | O2996: 1035 | P2996: 2.81 | Q2996: 147 | R2996: 692

Sheet Q2
A1: Sort ID | B1: Suburb | C1: Council Area 1 | D1: Council Area 2 | E1: Property Type | F1: Price | G1: Bedrooms | H1: Bathrooms | I1: Land Size (sqm) | J1: Year Built | K1: Sale Date | L1: Inspection Rating | M1: Agent Name | N1: Commission Rate (%) | O1: Council Rate ($/year) | P1: Distance to Nearest Station (km) | Q1: House Area (sqm) | R1: NAPLAN Score of Nearest School
A2: 5 | B2: Dee Why | E2: Apartment | F2: 1936967 | G2: 5 | H2: 1 | I2: 140 | J2: 1999 | K2: 45302 | L2: Good | M2: Ashley Brown | N2: 3.39 | O2: 1733 | P2: 3.32 | Q2: 302 | R2: 303
A3: 3 | B3: Berowra | E3: Villa | F3: 884945 | G3: 5 | H3: 2 | I3: 525 | J3: 2016 | K3: 45757 | L3: Poor | M3: Juan Martinez | N3: 2.47 | O3: 2294 | P3: 3.08 | Q3: 364 | R3: 520
A4: 4 | B4: Normanhurst | E4: House | F4: 526791 | G4: 2 | H4: 2 | I4: 691 | J4: 1951 | K4: 44957 | L4: Average | M4: Fernanda Lima | N4: 1.58 | O4: 2433 | P4: 2.54 | Q4: 146 | R4: 641
A5: 4 | B5: Granville | E5: Townhouse | F5: 962318 | G5: 6 | H5: 1 | I5: 491 | J5: 1990 | K5: 44415 | L5: Excellent | M5: Fatima Abiola | N5: 2.97 | O5: 1428 | P5: 3.04 | Q5: 392 | R5: 609
A6: 7 | B6: Dee Why | E6: House | F6: 2081519 | G6: 5 | H6: 2 | I6: 774 | J6: 1958 | K6: 45443 | L6: Average | M6: Carlos Silva | N6: 2.31 | O6: 1017 | P6: 1.43 | Q6: 309 | R6: 563
A7: 4 | B7: Earlwood | E7: House | F7: 2995613 | G7: 2 | H7: 2 | I7: 145 | J7: 1996 | K7: 45163 | L7: Good | M7: Mateusz Kowalski | N7: 2.68 | O7: 1568 | P7: 3.1 | Q7: 172 | R7: 512
A8: 7 | B8: Ultimo | E8: House | F8: 899433 | G8: 2 | H8: 1 | I8: 305 | J8: 1995 | K8: 44103 | L8: Good | M8: Jack Thompson | N8: 2.21 | O8: 2298 | P8: 4.07 | Q8: 122 | R8: 427
A9: 4 | B9: Hornsby | E9: House | F9: 1086020 | G9: 5 | H9: 3 | I9: 364 | J9: 2016 | K9: 44230 | L9: Average | M9: Mateusz Kowalski | N9: 2.47 | O9: 1250 | P9: 1.26 | Q9: 393 | R9: 431
A10: 3 | B10: Kensington | E10: Townhouse | F10: 1543087 | G10: 1 | H10: 1 | I10: 237 | J10: 1972 | K10: 44873 | L10: Excellent | M10: Sofia Rossi | N10: 2.15 | O10: 2068 | P10: 1.68 | Q10: 154 | R10: 569
A11: 1 | B11: Doonside | E11: Apartment | F11: 1866856 | G11: 3 | H11: 2 | I11: 832 | J11: 1990 | K11: 45550 | L11: Excellent | M11: Ashley Brown | N11: 1.72 | O11: 1843 | P11: 3.12 | Q11: 136 | R11: 410
A12: 0 | B12: Mount Druitt | E12: Apartment | F12: 2667413 | G12: 6 | H12: 2 | I12: 827 | J12: 2004 | K12: 45323 | L12: Excellent | M12: Chloe Wilson | N12: 3.3 | O12: 1568 | P12: 0.57 | Q12: 355 | R12: 426
A13: 5 | B13: Maroubra | E13: Villa | F13: 2373955 | G13: 2 | H13: 3 | I13: 885 | J13: 1965 | K13: 44448 | L13: Excellent | M13: Thabo Mokoena | N13: 2.38 | O13: 1779 | P13: 3.14 | Q13: 230 | R13: 426
... A32: 1 | B32: Maroubra | E32: Townhouse | F32: 2826982 | G32: 5 | H32: 1 | I32: 491 | J32: 2016 | K32: 44191 | L32: Average | M32: John Smith | N32: 2 | O32: 1513 | P32: 2.91 | Q32: 364 | R32: 579
A33: 8 | B33: Pymble | C33: =VLOOKUP(B33, 'Council Area'!A2:B51, 2) -> Ku-ring-gai Council | D33: =_xlfn.XLOOKUP(B33, 'Council Area'!A2:A51, 'Council Area'!B2:B51) -> Ku-ring-gai Council | E33: Townhouse | F33: 538096 | G33: 4 | H33: 1 | I33: 236 | J33: 1996 | K33: 45610 | L33: Excellent | M33: Lars Andersen | N33: 2.42 | O33: 1841 | P33: 3.87 | Q33: 243 | R33: 611
A34: 3 | B34: Mount Druitt | E34: Apartment | F34: 1697132 | G34: 3 | H34: 2 | I34: 51 | J34: 1970 | K34: 45745 | L34: Excellent | M34: Minh Nguyen | N34: 2.64 | O34: 1779 | P34: 0.48 | Q34: 263 | R34: 491
A35: 0 | B35: Gordon | E35: Villa | F35: 2140120 | G35: 6 | H35: 2 | I35: 139 | J35: 1993 | K35: 45157 | L35: Good | M35: Aisha Khan | N35: 1.98 | O35: 1699 | P35: 1.94 | Q35: 358 | R35: 310
A36: 4 | B36: Quakers Hill | E36: Apartment | F36: 2803271 | G36: 2 | H36: 2 | I36: 735 | J36: 2021 | K36: 45346 | L36: Poor | M36: Noah Anderson | N36: 1.65 | O36: 1025 | P36: 3.17 | Q36: 181 | R36: 339
A37: 1 | B37: Westmead | E37: Villa | F37: 1711359 | G37: 1 | H37: 2 | I37: 797 | J37: 1972 | K37: 44674 | L37: Excellent | M37: Mateusz Kowalski | N37: 1.7 | O37: 1217 | P37: 3.25 | Q37: 90 | R37: 381
A38: 8 | B38: Newtown | C38: =VLOOKUP(B38, 'Council Area'!$A$2:$B$51, 2) -> Inner West Council | D38: =_xlfn.XLOOKUP(B38, 'Council Area'!$A$2:$A$51, 'Council Area'!$B$2:$B$51) -> Inner West Council | E38: Townhouse | F38: 2488052 | G38: 0 | H38: 3 | I38: 632 | J38: 2011 | K38: 45680 | L38: Poor | M38: Thabo Mokoena | N38: 3.22 | O38: 1324 | P38: 2.96 | Q38: 77 | R38: 400
A39: 3 | B39: Harris Park | E39: House | F39: 2804395 | G39: 2 | H39: 2 | I39: 498 | J39: 1986 | K39: 44337 | L39: Good | M39: Olivia Martin | N39: 2.25 | O39: 1491 | P39: 0.44 | Q39: 238 | R39: 360
A40: 1 | B40: Thornleigh | E40: Apartment | F40: 485888 | G40: 1 | H40: 2 | I40: 692 | J40: 1952 | K40: 44663 | L40: Poor | M40: Lucia Torres | N40: 1.82 | O40: 1104 | P40: 3.13 | Q40: 70 | R40: 689
A41: 1 | B41: Randwick | E41: Apartment | F41: 2322754 | G41: 0 | H41: 2 | I41: 892 | J41: 1958 | K41: 45627 | L41: Good | M41: Thabo Mokoena | N41: 2.34 | O41: 1874 | P41: 3.46 | Q41: 45 | R41: 656
A42: 8 | B42: Northmead | C42: =VLOOKUP(B42, 'Council Area'!$A$2:$B$51, 2) -> Parramatta City Council | D42: =_xlfn.XLOOKUP(B42, 'Council Area'!$A$2:$A$51, 'Council Area'!$B$2:$B$51) -> Parramatta City Council | E42: Villa | F42: 1256488 | G42: 3 | H42: 2 | I42: 777 | J42: 1969 | K42: 44673 | L42: Poor | M42: Noah Anderson | N42: 3.4 | O42: 1041 | P42: 4.19 | Q42: 285 | R42: 665
A43: 3 | B43: Turramurra | E43: Townhouse | F43: 1736098 | G43: 5 | H43: 3 | I43: 128 | J43: 1973 | K43: 45501 | L43: Good | M43: Fatima Abiola | N43: 2.13 | O43: 1625 | P43: 3.09 | Q43: 274 | R43: 483
A44: 8 | B44: Balmain | C44: =VLOOKUP(B44, 'Council Area'!$A$2:$B$51, 2) -> Inner West Council | D44: =_xlfn.XLOOKUP(B44, 'Council Area'!$A$2:$A$51, 'Council Area'!$B$2:$B$51) -> Inner West Council | E44: Townhouse | F44: 1778980 | G44: 5 | H44: 3 | I44: 941 | J44: 2002 | K44: 45727 | L44: Poor | M44: John Smith | N44: 2.57 | O44: 2451 | P44: 4.06 | Q44: 373 | R44: 606
A45: 9 | B45: Glebe | E45: Villa | F45: 2524763 | G45: 3 | H45: 2 | I45: 349 | J45: 2005 | K45: 44082 | L45: Poor | M45: Carlos Silva | N45: 1.92 | O45: 1501 | P45: 3.66 | Q45: 115 | R45: 363
A46: 0 | B46: Pyrmont | E46: Apartment | F46: 2593186 | G46: 0 | H46: 2 | I46: 976 | J46: 1971 | K46: 44213 | L46: Average | M46: Nelson Maseko | N46: 1.66 | O46: 918 | P46: 0.11 | Q46: 42 | R46: 654
A47: 5 | B47: Ashfield | E47: Villa | F47: 2735765 | G47: 6 | H47: 1 | I47: 568 | J47: 2022 | K47: 44131 | L47: Excellent | M47: Elena Petrova | N47: 3.44 | O47: 2167 | P47: 3.33 | Q47: 333 | R47: 611
A48: 3 | B48: Manly | E48: House | F48: 1776997 | G48: 2 | H48: 3 | I48: 70 | J48: 2003 | K48: 45077 | L48: Poor | M48: Raj Patel | N48: 2.81 | O48: 953 | P48: 0.99 | Q48: 194 | R48: 625
A49: 5 | B49: Pymble | E49: Townhouse | F49: 1812186 | G49: 3 | H49: 3 | I49: 167 | J49: 1999 | K49: 45831 | L49: Average | M49: Chloe Wilson | N49: 3.25 | O49: 1187 | P49: 4.6 | Q49: 146 | R49: 573
A50: 6 | B50: Marrickville | E50: Townhouse | F50: 1854695 | G50: 3 | H50: 1 | I50: 901 | J50: 1971 | K50: 44103 | L50: Poor | M50: John Smith | N50: 2.25 | O50: 1887 | P50: 4.32 | Q50: 209 | R50: 529
A51: 2 | B51: Earlwood | E51: House | F51: 2020143 | G51: 4 | H51: 1 | I51: 254 | J51: 1972 | K51: 44645 | L51: Average | M51: Kwame Nkrumah | N51: 2.31 | O51: 1474 | P51: 1.45 | Q51: 292 | R51: 429
A52: 0 | B52: Coogee | E52: Apartment | F52: 2239543 | G52: 1 | H52: 2 | I52: 586 | J52: 1986 | K52: 44383 | L52: Average | M52: Lucia Torres | N52: 2.01 | O52: 2350 | P52: 2.55 | Q52: 65 | R52: 583
A53: 4 | B53: Berowra | E53: House | F53: 1690089 | G53: 3 | H53: 2 | I53: 505 | J53: 1972 | K53: 45220 | L53: Average | M53: Raj Patel | N53: 3.42 | O53: 1966 | P53: 1.37 | Q53: 315 | R53: 658
A54: 2 | B54: Granville | E54: Villa | F54: 1579632 | G54: 4 | H54: 1 | I54: 714 | J54: 1959 | K54: 44561 | L54: Average | M54: Diego Ramirez | N54: 2.62 | O54: 2061 | P54: 2.14 | Q54: 163 | R54: 310
A55: 9 | B55: Gordon | E55: House | F55: 494147 | G55: 3 | H55: 1 | I55: 790 | J55: 1953 | K55: 45183 | L55: Poor | M55: Maria Gonzalez | N55: 1.8 | O55: 2062 | P55: 3.05 | Q55: 184 | R55: 408
A56: 8 | B56: Bankstown | C56: =VLOOKUP(B56, 'Council Area'!$A$2:$B$51, 2) -> Canterbury-Bankstown Council | D56: =_xlfn.XLOOKUP(B56, 'Council Area'!$A$2:$A$51, 'Council Area'!$B$2:$B$51) -> Canterbury-Bankstown Council | E56: Apartment | F56: 2085921 | G56: 6 | H56: 1 | I56: 998 | J56: 2021 | K56: 44512 | L56: Excellent | M56: Carlos Silva | N56: 1.52 | O56: 1700 | P56: 4.09 | Q56: 355 | R56: 450
A57: 6 | B57: Marrickville | E57: House | F57: 1265093 | G57: 2 | H57: 1 | I57: 784 | J57: 1979 | K57: 44742 | L57: Excellent | M57: Olivia Martin | N57: 2.59 | O57: 1356 | P57: 1.05 | Q57: 227 | R57: 337
A58: 3 | B58: Lakemba | E58: House | F58: 980954 | G58: 2 | H58: 1 | I58: 627 | J58: 2000 | K58: 44894 | L58: Average | M58: Jack Thompson | N58: 3.44 | O58: 2452 | P58: 3.04 | Q58: 116 | R58: 572
...

Sheet Q3
A1: Price
A2: 538096 | C2: Mean | D2: =AVERAGE(A2:A296) -> 1646657.1
A3: 2488052 | C3: Median | D3: =MEDIAN(A2:A296) -> 1609946
A4: 1256488 | C4: Mode | D4: {=_xlfn.MODE.MULT(A2:A296)} -> #N/A
A5: 1778980 | C5: Range | D5: =MAX(A2:A296)-MIN(A2:A296) -> 2586268
A6: 2085921 | C6: Interquartile Range | D6: =_xlfn.QUARTILE.INC(A2:A296, 3) - _xlfn.QUARTILE.INC(A2:A296, 1) -> 1188088
A7: 1484200 | C7: Variance | D7: =_xlfn.VAR.S(A2:A296) -> 5.2411723e+11
A8: 1226492 | C8: Standard Deviation | D8: =_xlfn.STDEV.S(A2:A296) -> 723959.41
A9: 2518595 | C9: Coefficient of Variation | D9: =D8/D2 -> 0.43965401
A10: 2729157
A11: 2340435
A12: 2162008
A13: 517794
A14: 551879
A15: 2630926
A16: 530849
A17: 912151
A18: 2358256
A19: 1715874
A20: 2391665
A21: 1752561
... A296: 666648

Sheet Q3 Graph
A1: Price | B1: Bins
A2: 538096 | B2: 600000
A3: 2488052 | B3: 800000
A4: 1256488 | B4: 1000000
A5: 1778980 | B5: 1200000
A6: 2085921 | B6: 1400000
A7: 1484200 | B7: 1600000 | D7: Bins | E7: Frequency
A8: 1226492 | B8: 1800000 | D8: 600000 | E8: 22
A9: 2518595 | B9: 2000000 | D9: 800000 | E9: 18
A10: 2729157 | B10: 2200000 | D10: 1000000 | E10: 29
A11: 2340435 | B11: 2400000 | D11: 1200000 | E11: 24
A12: 2162008 | B12: 2600000 | D12: 1400000 | E12: 29
A13: 517794 | B13: 2800000 | D13: 1600000 | E13: 24
A14: 551879 | B14: 3000000 | D14: 1800000 | E14: 34
A15: 2630926 | D15: 2000000 | E15: 18
A16: 530849 | D16: 2200000 | E16: 21
A17: 912151 | D17: 2400000 | E17: 15
A18: 2358256 | D18: 2600000 | E18: 23
A19: 1715874 | D19: 2800000 | E19: 21
A20: 2391665 | D20: 3000000 | E20: 17
A21: 1752561 | D21: More | E21: 0
A22: 1185465
A23: 567597
A24: 679961
A25: 556626
A26: 1729801
A27: 2966416
A28: 1308029
A29: 2124077
A30: 885651
A31: 2518011
A32: 765646
A33: 533729
... A296: 666648

Sheet Q4
A1: Price
A2: 884945
A3: 2373955 | C3: sample mean | D3: =AVERAGE(A2:A726) -> 1687142.1
A4: 2744360 | C4: standard deviation | D4: =_xlfn.STDEV.S(A2:A726) -> 774484.38
A5: 1745804 | C5: sample size | D5: 725
A6: 523033 | C6: test stat | D6: =(D3-1675000)/(D4/SQRT(D5)) -> 0.42213221
A7: 1151269
A8: 2662784
A9: 2140120
A10: 1711359
A11: 1256488
A12: 2524763
A13: 2735765
A14: 1579632
A15: 1995915
A16: 1833385
A17: 2914399
A18: 2376880
... A726: 2198996

Sheet Q5
A1: Bedrooms | B1: House Area
A2: 4 | B2: 243 | D2: Correlation coefficient | E2: =CORREL(A2:A296,B2:B296) -> 0.83971718
A3: 0 | B3: 77 | D3: T stat | E3: =E2/(SQRT(1-E2^2)/SQRT(293)) -> 26.469627
A4: 3 | B4: 285 | D4: crit value | E4: =_xlfn.T.INV(1-0.05, 295-2) -> 1.6500708
A5: 5 | B5: 373
A6: 6 | B6: 355
A7: 2 | B7: 116
A8: 0 | B8: 72
A9: 3 | B9: 290
A10: 1 | B10: 157
A11: 5 | B11: 397
A12: 3 | B12: 97
A13: 4 | B13: 270
A14: 2 | B14: 198
A15: 4 | B15: 254
A16: 3 | B16: 303
... A296: 5 | B296: 372

Sheet Q5 Graph
A1: Bedrooms | B1: House Area
A2: 4 | B2: 243
A3: 0 | B3: 77
A4: 3 | B4: 285
A5: 5 | B5: 373
A6: 6 | B6: 355
A7: 2 | B7: 116
A8: 0 | B8: 72
A9: 3 | B9: 290
A10: 1 | B10: 157
A11: 5 | B11: 397
A12: 3 | B12: 97
A13: 4 | B13: 270
... A296: 5 | B296: 372

Sheet Q6
B1: Bedrooms | C1: Bathrooms | D1: House Area (sqm)
B2: 4 | C2: 1 | D2: 243
B3: 0 | C3: 3 | D3: 77
B4: 3 | C4: 2 | D4: 285
B5: 5 | C5: 3 | D5: 373
B6: 6 | C6: 1 | D6: 355
B7: 2 | C7: 2 | D7: 116
B8: 0 | C8: 2 | D8: 72
B9: 3 | C9: 2 | D9: 290
B10: 1 | C10: 2 | D10: 157
B11: 5 | C11: 3 | D11: 397
B12: 3 | C12: 2 | D12: 97
B13: 4 | C13: 3 | D13: 270
... B17: 0 | C17: 1 | D17: 71
B18: 4 | C18: 1 | D18: 389 | G18: Summary Output
B19: 5 | C19: 3 | D19: 390 | G19: Regression Statistics
B20: 2 | C20: 1 | D20: 127 | G20: Multiple R | H20: 0.83981634
B21: 1 | C21: 3 | D21: 94 | G21: R Square | H21: 0.70529148
B22: 5 | C22: 3 | D22: 322 | G22: Adjusted R Square | H22: 0.70327293
B23: 5 | C23: 1 | D23: 272 | G23: Standard Error | H23: 58.484339
B24: 5 | C24: 1 | D24: 316 | G24: Observations | H24: 295
B25: 5 | C25: 3 | D25: 345
B26: 3 | C26: 2 | D26: 136 | G26: ANOVA
B27: 3 | C27: 3 | D27: 180 | H27: df | I27: SS | J27: MS | K27: F | L27: Significance F
B28: 5 | C28: 2 | D28: 295 | G28: Regression | H28: 2 | I28: 2390220.5 | J28: 1195110.3 | K28: 349.40474 | L28: 3.3988616e-78
B29: 3 | C29: 1 | D29: 160 | G29: Residual | H29: 292 | I29: 998762.04 | J29: 3420.4179
B30: 6 | C30: 2 | D30: 345 | G30: Total | H30: 294 | I30: 3388982.5
B31: 3 | C31: 3 | D31: 279
B32: 4 | C32: 2 | D32: 291 | G32: Coefficients
B33: 5 | C33: 2 | D33: 396 | H33: Coefficients | I33: Standard Error | J33: t Stat | K33: P-value | L33: Lower 95% | M33: Upper 95% | N33: Lower 95.0% | O33: Upper 95.0%
B34: 2 | C34: 3 | D34: 199 | G34: Intercept | H34: 42.283303 | I34: 10.87119 | J34: 3.8894824 | K34: 0.00012444572 | L34: 20.887481 | M34: 63.679125 | N34: 20.887481 | O34: 63.679125
B35: 2 | C35: 2 | D35: 183 | G35: Bedrooms | H35: 56.628113 | I35: 2.1499213 | J35: 26.339621 | K35: 3.9703782e-79 | L35: 52.396807 | M35: 60.85942 | N35: 52.396807 | O35: 60.85942
B36: 3 | C36: 2 | D36: 315 | G36: Bathrooms | H36: -1.7372187 | I36: 4.2765753 | J36: -0.40621727 | K36: 0.68488051 | L36: -10.154038 | M36: 6.6796007 | N36: -10.154038 | O36: 6.6796007
B37: 3 | C37: 2 | D37: 181
B38: 1 | C38: 2 | D38: 81 | G38: RESIDUAL OUTPUT
B39: 3 | C39: 3 | D39: 156
B40: 5 | C40: 1 | D40: 297 | G40: Observation | H40: Predicted House Area (sqm) | I40: Residuals
B41: 4 | C41: 2 | D41: 212 | G41: 1 | H41: 267.05854 | I41: -24.058538
B42: 4 | C42: 3 | D42: 358 | G42: 2 | H42: 37.071647 | I42: 39.928353
B43: 1 | C43: 2 | D43: 96 | G43: 3 | H43: 208.69321 | I43: 76.306794
...

Sheet Q7
A1: Apartment Price | B1: House Price
A2: 2085921 | B2: 1226492
A3: 1484200 | B3: 2630926
A4: 2518595 | B4: 1715874
A5: 2729157 | B5: 2391665 | D5: t-Test: Two-Sample Assuming Unequal Variances
A6: 2340435 | B6: 1752561
A7: 530849 | B7: 679961 | E7: Apartment Price | F7: House Price
A8: 912151 | B8: 885651 | D8: Mean | E8: 1578217.9 | F8: 1718257.1
A9: 2358256 | B9: 2518011 | D9: Variance | E9: 5.3174769e+11 | F9: 5.4973818e+11
A10: 1308029 | B10: 568454 | D10: Observations | E10: 69 | F10: 74
A11: 533729 | B11: 1388611 | D11: Hypothesised Mean Difference | E11: 0
A12: 665192 | B12: 2043730 | D12: df | E12: 141
A13: 1041720 | B13: 1114283 | D13: t Stat | E13: -1.1382895
A14: 2170715 | B14: 2596536 | D14: P(T<=t) one-tail | E14: 0.12846501
A15: 1573906 | B15: 1912787 | D15: t Critical one-tail | E15: 1.6557323
A16: 1468035 | B16: 2727723 | D16: P(T<=t) two-tail | E16: 0.25693002
A17: 2402702 | B17: 2475314 | D17: t Critical two-tail | E17: 1.9769315
A18: 1396903 | B18: 1746840
A19: 1722194 | B19: 626405
A20: 2748095 | B20: 2626318
A21: 2284048 | B21: 2685724
A22: 1358231 | B22: 638495
A23: 1301498 | B23: 2983596
A24: 2117875 | B24: 1755361
A25: 879288 | B25: 2541458
A26: 1234229 | B26: 713648
A27: 821330 | B27: 834664
A28: 2677009 | B28: 2459040
A29: 2495977 | B29: 2381021
... A70: 666648 | B70: 1727663
B71: 837794
B72: 1776972
B73: 2442992
B74: 1079105
B75: 1211415

Sheet Q8
A1: Apartment Prices | B1: Townhouse Prices | C1: House Prices | D1: Villa Prices
A2: 2085921 | B2: 538096 | C2: 1226492 | D2: 1256488
A3: 1484200 | B3: 2488052 | C3: 2630926 | D3: 517794
A4: 2518595 | B4: 1778980 | C4: 1715874 | D4: 551879
A5: 2729157 | B5: 2162008 | C5: 2391665 | D5: 1185465
A6: 2340435 | B6: 567597 | C6: 1752561 | D6: 1729801
A7: 530849 | B7: 556626 | C7: 679961 | D7: 2966416 | G7: Summary
A8: 912151 | B8: 2124077 | C8: 885651 | D8: 765646 | G8: Groups | H8: Count | I8: Sum | J8: Average | K8: Variance
A9: 2358256 | B9: 1562336 | C9: 2518011 | D9: 2413424 | G9: Apartment Prices | H9: 69 | I9: 108897037 | J9: 1578217.9 | K9: =TEXT(P9, "0.00") -> 531747690531.25 | P9: 5.3174769e+11
A10: 1308029 | B10: 580179 | C10: 568454 | D10: 2596099 | G10: Townhouse Prices | H10: 79 | I10: 129167881 | J10: 1635036.5 | K10: =TEXT(P10, "0.00") -> 503272132484.77 | P10: 5.0327213e+11
A11: 533729 | B11: 987676 | C11: 1388611 | D11: 1272387 | G11: House Prices | H11: 74 | I11: 127151023 | J11: 1718257.1 | K11: =TEXT(P11, "0.00") -> 549738184666.53 | P11: 5.4973818e+11
A12: 665192 | B12: 2755253 | C12: 2043730 | D12: 1528674 | G12: Villa Prices | H12: 73 | I12: 120547910 | J12: 1651341.2 | K12: =TEXT(P12, "0.00") -> 525426147639.65 | P12: 5.2542615e+11
A13: 1041720 | B13: 1340353 | C13: 1114283 | D13: 2623285
A14: 2170715 | B14: 2746789 | C14: 2596536 | D14: 1999873
A15: 1573906 | B15: 1152022 | C15: 1912787 | D15: 1829169 | G15: ANOVA
A16: 1468035 | B16: 1224555 | C16: 2727723 | D16: 1993191 | G16: Source of Variation | H16: SS | I16: df | J16: MS | K16: F | L16: P-value | M16: F crit
A17: 2402702 | B17: 1609946 | C17: 2475314 | D17: 1709116 | G17: Between Groups | H17: =TEXT(714825386585.594, "0.00") -> 714825386585.59 | I17: 3 | J17: =TEXT(238275128861.865, "0.00") -> 238275128861.87 | K17: 0.45208002 | L17: 0.71601932 | M17: 2.6356288
A18: 1396903 | B18: 1305593 | C18: 1746840 | D18: 1543508 | G18: Within Groups | H18: =TEXT(153375639400648, "0") -> 153375639400648 | I18: 291 | J18: =TEXT(527064052923.189, "0.00") -> 527064052923.19
A19: 1722194 | B19: 2614176 | C19: 626405 | D19: 2807269 | G19: Total | H19: =TEXT(154090464787234, "0") -> 154090464787234 | I19: 294
A20: 2748095 | B20: 1285009 | C20: 2626318 | D20: 2368590
A21: 2284048 | B21: 1315915 | C21: 2685724 | D21: 552627
A22: 1358231 | B22: 1939588 | C22: 638495 | D22: 2185537
A23: 1301498 | B23: 1320577 | C23: 2983596 | D23: 522380
A24: 2117875 | B24: 889504 | C24: 1755361 | D24: 452515
A25: 879288 | B25: 1671063 | C25: 2541458 | D25: 1048416
A26: 1234229 | B26: 2840451 | C26: 713648 | D26: 1150822
A27: 821330 | B27: 2295373 | C27: 834664 | D27: 2285903
A28: 2677009 | B28: 1659623 | C28: 2459040 | D28: 2219875
A29: 2495977 | B29: 1208118 | C29: 2381021 | D29: 2565825
A30: 1397786 | B30: 455574 | C30: 2783962 | D30: 1324794
A31: 752101 | B31: 1612427 | C31: 2722791 | D31: 2749545
... A70: 666648 | B70: 2068093 | C70: 1727663 | D70: 1112507
B71: 1681441 | C71: 837794 | D71: 2142229
B72: 2239962 | C72: 1776972 | D72: 2055041
B73: 1326513 | C73: 2442992 | D73: 1415642
B74: 2477857 | C74: 1079105 | D74: 553402
B75: 2179934 | C75: 1211415
B76: 436659
B77: 751690
B78: 1793484
...

Sheet Council Area
A1: Suburb | B1: Council Area
A2: Ashfield | B2: Inner West Council
A3: Asquith | B3: Hornsby Shire Council
A4: Balmain | B4: Inner West Council
A5: Bankstown | B5: Canterbury-Bankstown Council
A6: Berowra | B6: Hornsby Shire Council
A7: Blacktown | B7: Blacktown City Council
A8: Brookvale | B8: Northern Beaches Council
A9: Campsie | B9: Canterbury-Bankstown Council
A10: Coogee | B10: Randwick City Council
A11: Cronulla | B11: Sutherland Shire Council
A12: Dee Why | B12: Northern Beaches Council
... A51: Westmead | B51: Parramatta City Council
